Workbook

Sheet Sustainability Impact Analysis
A1: Project | Sustainability Impact Analysis for Intel | F1: =ROWS(I2:I19721) -> 19720 | H1: 0 | I1: device_type | J1: model_year | K1: device_age | L1: power_consumption | M1: energy_savings_yr | N1: co2_saved_kg_yr | O1: region | P1: recycling_rate | S1: =_xlfn.CONCAT(Table2[n_devices]) -> 100319625683463035951706785355
H2: LP16AS29999 | I2: Laptop | J2: 2016 | K2: =2024 -impact_data[[#This Row],[model_year]] -> 8 | L2: 61 | M2: 87.3 | N2: 52.4 | O2: Asia | P2: 0.86 | R2: =AVERAGEIF($J$2:$J$19720, I8, $M$2:$M$19720) -> #DIV/0! | S2: =AVERAGE(Table2[avg_energy_saved]) -> 2.8801222
H3: LP16NA84519 | I3: Laptop | J3: 2016 | K3: =2024 -impact_data[[#This Row],[model_year]] -> 8 | L3: 62 | M3: 49.2 | N3: 19.7 | O3: North America | P3: 0.87
A4: Part 1: Organizing and Understanding the Data | H4: LP16NA75384 | I4: Laptop | J4: 2016 | K4: =2024 -impact_data[[#This Row],[model_year]] -> 8 | L4: 60 | M4: 48.5 | N4: 19.4 | O4: North America | P4: 0.86
H5: LP16AS35967 | I5: Laptop | J5: 2016 | K5: =2024 -impact_data[[#This Row],[model_year]] -> 8 | L5: 59 | M5: 36.2 | N5: 21.7 | O5: Asia | P5: 0.89
A6: 1 | B6: How many columns take on numeric values? | C6: 6 | H6: LP16AS94069 | I6: Laptop | J6: 2016 | K6: =2024 -impact_data[[#This Row],[model_year]] -> 8 | L6: 64 | M6: 53.4 | N6: 32 | O6: Asia | P6: 0.87
A7: 2 | B7: How many columns take on text values? | C7: 3 | H7: LP16NA85163 | I7: Laptop | J7: 2016 | K7: =2024 -impact_data[[#This Row],[model_year]] -> 8 | L7: 60 | M7: 58 | N7: 23.2 | O7: North America | P7: 0.87
A8: 3 | B8: Calculate the age of each device by subtracting the model_year from 2024, the year this data was collected. Enter your formula in the device_age column. For example, a 2019 device should be 5 years old. | H8: DT16NA26198 | I8: Desktop | J8: 2016 | K8: =2024 -impact_data[[#This Row],[model_year]] -> 8 | L8: 89 | M8: 27 | N8: 10.8 | O8: North America | P8: 0.97
H9: DT16NA51953 | I9: Desktop | J9: 2016 | K9: =2024 -impact_data[[#This Row],[model_year]] -> 8 | L9: 90 | M9: 95.2 | N9: 38.1 | O9: North America | P9: 0.95
A10: 4 | B10: Sort the data by model_year (oldest to newest). Do you notice more older (5+ years) or newer (under 5 years) devices being repurposed? What might that indicate? | H10: LP16NA89088 | I10: Laptop | J10: 2016 | K10: =2024 -impact_data[[#This Row],[model_year]] -> 8 | L10: 63 | M10: 58.7 | N10: 23.5 | O10: North America | P10: 0.88
H11: LP16NA24120 | I11: Laptop | J11: 2016 | K11: =2024 -impact_data[[#This Row],[model_year]] -> 8 | L11: 63 | M11: 32.5 | N11: 13 | O11: North America | P11: 0.87
A12: The data shows that there are a lot more newer devices being repurposed than older devices. It could indicate a few things, that there aren't as many older devices in the hands of people who know how to update them, or people just don't have the devices anymore. I know most people probably don't consider updating them, possibly thinking its just easier and better to buy new. | H12: LP16AS54821 | I12: Laptop | J12: 2016 | K12: =2024 -impact_data[[#This Row],[model_year]] -> 8 | L12: 63 | M12: 83 | N12: 49.8 | O12: Asia | P12: 0.86
H13: LP16AS39987 | I13: Laptop | J13: 2016 | K13: =2024 -impact_data[[#This Row],[model_year]] -> 8 | L13: 62 | M13: 41.2 | N13: 24.7 | O13: Asia | P13: 0.87
H14: LP16AS19099 | I14: Laptop | J14: 2016 | K14: =2024 -impact_data[[#This Row],[model_year]] -> 8 | L14: 66 | M14: 62.5 | N14: 37.5 | O14: Asia | P14: 0.89
A15: Part 2: Key Insights | H15: LP16NA32599 | I15: Laptop | J15: 2016 | K15: =2024 -impact_data[[#This Row],[model_year]] -> 8 | L15: 61 | M15: 27.3 | N15: 10.9 | O15: North America | P15: 0.89
H16: LP16NA66751 | I16: Laptop | J16: 2016 | K16: =2024 -impact_data[[#This Row],[model_year]] -> 8 | L16: 61 | M16: 41.5 | N16: 16.6 | O16: North America | P16: 0.89
A17: 1 | B17: What is the total number of devices Intel repurposed? Note: All devices in the table impact_data were repurposed. | C17: =COUNT(J2:J19720) -> 19719 | H17: DT16AS22428 | I17: Desktop | J17: 2016 | K17: =2024 -impact_data[[#This Row],[model_year]] -> 8 | L17: 86 | M17: 42.1 | N17: 25.3 | O17: Asia | P17: 0.97
H18: LP16NA62514 | I18: Laptop | J18: 2016 | K18: =2024 -impact_data[[#This Row],[model_year]] -> 8 | L18: 61 | M18: 71.5 | N18: 28.6 | O18: North America | P18: 0.88
A19: 2 | B19: Using the AVERAGE() function, what is the average age of repurposed devices? | C19: 3.9069933 | H19: LP16AS65653 | I19: Laptop | J19: 2016 | K19: =2024 -impact_data[[#This Row],[model_year]] -> 8 | L19: 61 | M19: 22.9 | N19: 13.8 | O19: Asia | P19: 0.87
H20: LP16NA20113 | I20: Laptop | J20: 2016 | K20: =2024 -impact_data[[#This Row],[model_year]] -> 8 | L20: 64 | M20: 65.1 | N20: 26 | O20: North America | P20: 0.86
A21: 3 | B21: What is the average estimated energy savings (kWh) from repurposed devices per year compared to new devices? | C21: =AVERAGE(impact_data[energy_savings_yr]) -> 28.431376 | H21: DT16NA97962 | I21: Desktop | J21: 2016 | K21: =2024 -impact_data[[#This Row],[model_year]] -> 8 | L21: 89 | M21: 33.7 | N21: 13.5 | O21: North America | P21: 0.95
H22: LP16AS64758 | I22: Laptop | J22: 2016 | K22: =2024 -impact_data[[#This Row],[model_year]] -> 8 | L22: 65 | M22: 45.2 | N22: 27.1 | O22: Asia | P22: 0.88
A23: 4 | B23: What is the total CO₂ emissions saved (in tons) from repurposed devices? | C23: 276.18 | D23: Hint! | H23: LP16NA59054 | I23: Laptop | J23: 2016 | K23: =2024 -impact_data[[#This Row],[model_year]] -> 8 | L23: 59 | M23: 66.5 | N23: 26.6 | O23: North America | P23: 0.86
A24: 5 | B24: Now that you have calculated the average estimated energy savings (kWh) and CO₂ emissions saved (tons), use ChatGPT to help put these numbers into perspective. Summarize how much energy and CO₂ emissions were saved and how it compares to something familiar, like powering households or reducing car emissions. | H24: DT16AS11375 | I24: Desktop | J24: 2016 | K24: =2024 -impact_data[[#This Row],[model_year]] -> 8 | L24: 89 | M24: 62.1 | N24: 37.3 | O24: Asia | P24: 0.94
H25: LP16NA85983 | I25: Laptop | J25: 2016 | K25: =2024 -impact_data[[#This Row],[model_year]] -> 8 | L25: 59 | M25: 57.9 | N25: 23.2 | O25: North America | P25: 0.88
H26: DT16AS32930 | I26: Desktop | J26: 2016 | K26: =2024 -impact_data[[#This Row],[model_year]] -> 8 | L26: 88 | M26: 29.2 | N26: 17.5 | O26: Asia | P26: 0.93
H27: LP16EU91551 | I27: Laptop | J27: 2016 | K27: =2024 -impact_data[[#This Row],[model_year]] -> 8 | L27: 60 | M27: 68.5 | N27: 17.1 | O27: Europe | P27: 0.87
A28: Try This Prompt: I found that each repurposed device saves approximately of XXX kWh of energy per year and Intel's repurposing program saved XXX tons of CO₂ emissions in one year. Help me understand the significance of these numbers. How would this compare to the energy consumption of a small city or the amount of CO₂ produced by cars? What is the environmental impact of these savings? | H28: LP16AS84096 | I28: Laptop | J28: 2016 | K28: =2024 -impact_data[[#This Row],[model_year]] -> 8 | L28: 65 | M28: 37.7 | N28: 22.6 | O28: Asia | P28: 0.86
H29: DT16AS97056 | I29: Desktop | J29: 2016 | K29: =2024 -impact_data[[#This Row],[model_year]] -> 8 | L29: 90 | M29: 36.6 | N29: 22 | O29: Asia | P29: 0.96
H30: LP16NA79909 | I30: Laptop | J30: 2016 | K30: =2024 -impact_data[[#This Row],[model_year]] -> 8 | L30: 61 | M30: 79.2 | N30: 31.7 | O30: North America | P30: 0.89
H31: LP16EU52699 | I31: Laptop | J31: 2016 | K31: =2024 -impact_data[[#This Row],[model_year]] -> 8 | L31: 64 | M31: 90.7 | N31: 22.7 | O31: Europe | P31: 0.86
A32: Intel's repurposing program saves 28.4 kWh per device yearly—matching one US household's daily electricity use—and totals ~284,000 kWh across ~10,000 devices, powering 27 average US homes or 36 Michigan homes annually. 276 metric tons CO₂ saved equals emissions from 60 cars driven one year (4.6 tons/car).Savings are tiny vs. a small city's billions of kWh yearly (e.g., 0.000024% of Nashville's) | H32: LP16AS31398 | I32: Laptop | J32: 2016 | K32: =2024 -impact_data[[#This Row],[model_year]] -> 8 | L32: 59 | M32: 23.9 | N32: 14.4 | O32: Asia | P32: 0.86
H33: LP16NA86382 | I33: Laptop | J33: 2016 | K33: =2024 -impact_data[[#This Row],[model_year]] -> 8 | L33: 63 | M33: 39.4 | N33: 15.8 | O33: North America | P33: 0.88
H34: LP16NA73118 | I34: Laptop | J34: 2016 | K34: =2024 -impact_data[[#This Row],[model_year]] -> 8 | L34: 65 | M34: 88.8 | N34: 35.5 | O34: North America | P34: 0.88
H35: LP16AS61074 | I35: Laptop | J35: 2016 | K35: =2024 -impact_data[[#This Row],[model_year]] -> 8 | L35: 60 | M35: 44.2 | N35: 26.5 | O35: Asia | P35: 0.86
A36: Part 3: Deeper Patterns and Trends | H36: LP16AS56283 | I36: Laptop | J36: 2016 | K36: =2024 -impact_data[[#This Row],[model_year]] -> 8 | L36: 61 | M36: 9.4 | N36: 5.6 | O36: Asia | P36: 0.86
H37: LP16AS61581 | I37: Laptop | J37: 2016 | K37: =2024 -impact_data[[#This Row],[model_year]] -> 8 | L37: 64 | M37: 59 | N37: 35.4 | O37: Asia | P37: 0.88
A38: 1 | B38: Using the COUNTIF() function, how many laptops were repurposed? | C38: =COUNTIF($I$2:$I$19720, I37) -> 16512 | H38: LP16NA82540 | I38: Laptop | J38: 2016 | K38: =2024 -impact_data[[#This Row],[model_year]] -> 8 | L38: 60 | M38: 17.1 | N38: 6.8 | O38: North America | P38: 0.88
A39: 2 | B39: Using the COUNTIF() function, how many desktops were repurposed? | C39: =COUNTIF($I$2:$I$19720, I8) -> 3207 | H39: LP16EU77944 | I39: Laptop | J39: 2016 | K39: =2024 -impact_data[[#This Row],[model_year]] -> 8 | L39: 60 | M39: 45.7 | N39: 11.4 | O39: Europe | P39: 0.89
A40: 3 | B40: Using the AVERAGEIF() function, what is the average energy savings for repurposing laptops? | C40: =AVERAGEIF(I2:I19720,"Laptop",M2:M19720) -> 28.365855 | H40: LP16EU15738 | I40: Laptop | J40: 2016 | K40: =2024 -impact_data[[#This Row],[model_year]] -> 8 | L40: 64 | M40: 62.3 | N40: 15.6 | O40: Europe | P40: 0.89
...

Sheet Data Dictionary
A1: Data Dictionary
A3: Column Name | B3: Description
A4: Device ID | B4: Unique identifier for each repurposed device
A5: Device Type | B5: Type of device, values are either "Laptop" or "Desktop"
A6: Model Year | B6: The year the device was manufactured (e.g., 2018, 2019, etc.).
A7: Power Consumption (W) | B7: Power consumption of the device in watts (W) when in use (e.g., 50W, 75W).
A8: Energy Savings (kWh) | B8: Estimated energy savings per device per year when repurposed compared to a new device, measured in kilowatt-hours (kWh).
A9: CO2 Saved | B9: Estimated CO2 emissions saved per device per year from manufacturing a new device, measured in tons.
A10: Region | B10: The geographical region where the device was repurposed, values are "North America", "Europe", and "Asia”
A11: Device Age (Years) | B11: The age of the device at the time it was repurposed, calculated as the difference between the current year and the model year.
A12: Recycling Rate (%) | B12: The percentage of the device that is recyclable

Sheet Sheet1

Sheet Solutions
A1: Question | B1: Value | C1: Tolerance | D1: student-solution | E1: student-formula
A2: Part 1, 1 | B2: 6 | D2: =IF(ISBLANK(INDEX('Sustainability Impact Analysis'!$C$6,1,1)), "no solution", IF(ISERROR(INDEX('Sustainability Impact Analysis'!$C$6,1,1)), "error in parsing the solution", INDEX('Sustainability Impact Analysis'!$C$6,1,1))) -> 6 | E2: =IFERROR(_xlfn.FORMULATEXT(INDEX('Sustainability Impact Analysis'!$C$6,1,1)),"no formula necessary") -> no formula necessary
A3: Part 1, 2 | B3: 3 | D3: =IF(ISBLANK(INDEX('Sustainability Impact Analysis'!$C$7,1,1)), "no solution", IF(ISERROR(INDEX('Sustainability Impact Analysis'!$C$7,1,1)), "error in parsing the solution", INDEX('Sustainability Impact Analysis'!$C$7,1,1))) -> 3 | E3: =IFERROR(_xlfn.FORMULATEXT(INDEX('Sustainability Impact Analysis'!$C$7,1,1)),"no formula necessary") -> no formula necessary
A4: Part 2, 1 | B4: 19719 | D4: =IF(ISBLANK(INDEX('Sustainability Impact Analysis'!$C$17,1,1)), "no solution", IF(ISERROR(INDEX('Sustainability Impact Analysis'!$C$17,1,1)), "error in parsing the solution", INDEX('Sustainability Impact Analysis'!$C$17,1,1))) -> 19719 | E4: =IFERROR(_xlfn.FORMULATEXT(INDEX('Sustainability Impact Analysis'!$C$17,1,1)),"no formula") -> =COUNT(J2:J19720)
A5: Part 2, 2 | B5: 3.9069933 | C5: 0.01 | D5: =IF(ISBLANK(INDEX('Sustainability Impact Analysis'!$C$19,1,1)), "no solution", IF(ISERROR(INDEX('Sustainability Impact Analysis'!$C$19,1,1)), "error in parsing the solution", INDEX('Sustainability Impact Analysis'!$C$19,1,1))) -> 3.9069933 | E5: =IFERROR(_xlfn.FORMULATEXT(INDEX('Sustainability Impact Analysis'!$C$19,1,1)),"no formula") -> no formula
A6: Part 2, 3 | B6: 28.431376 | C6: 0.01 | D6: =IF(ISBLANK(INDEX('Sustainability Impact Analysis'!$C$21,1,1)), "no solution", IF(ISERROR(INDEX('Sustainability Impact Analysis'!$C$21,1,1)), "error in parsing the solution", INDEX('Sustainability Impact Analysis'!$C$21,1,1))) -> 28.431376 | E6: =IFERROR(_xlfn.FORMULATEXT(INDEX('Sustainability Impact Analysis'!$C$21,1,1)),"no formula") -> =AVERAGE(impact_data[energy_savings_yr])
A7: Part 2, 4 | B7: 276.1817 | C7: 0.01 | D7: =IF(ISBLANK(INDEX('Sustainability Impact Analysis'!$C$23,1,1)), "no solution", IF(ISERROR(INDEX('Sustainability Impact Analysis'!$C$23,1,1)), "error in parsing the solution", INDEX('Sustainability Impact Analysis'!$C$23,1,1))) -> 276.18 | E7: =IFERROR(_xlfn.FORMULATEXT(INDEX('Sustainability Impact Analysis'!$C$23,1,1)),"no formula") -> no formula
A8: Part 3, 1 | B8: 16512 | D8: =IF(ISBLANK(INDEX('Sustainability Impact Analysis'!$C$38,1,1)), "no solution", IF(ISERROR(INDEX('Sustainability Impact Analysis'!$C$38,1,1)), "error in parsing the solution", INDEX('Sustainability Impact Analysis'!$C$38,1,1))) -> 16512 | E8: =IFERROR(_xlfn.FORMULATEXT(INDEX('Sustainability Impact Analysis'!$C$38,1,1)),"no formula") -> =COUNTIF($I$2:$I$19720, I37)
A9: Part 3, 2 | B9: 3207 | D9: =IF(ISBLANK(INDEX('Sustainability Impact Analysis'!$C$39,1,1)), "no solution", IF(ISERROR(INDEX('Sustainability Impact Analysis'!$C$39,1,1)), "error in parsing the solution", INDEX('Sustainability Impact Analysis'!$C$39,1,1))) -> 3207 | E9: =IFERROR(_xlfn.FORMULATEXT(INDEX('Sustainability Impact Analysis'!$C$39,1,1)),"no formula") -> =COUNTIF($I$2:$I$19720, I8)
A10: Part 3, 3 | B10: 28.365855 | C10: 0.01 | D10: =IF(ISBLANK(INDEX('Sustainability Impact Analysis'!$C$40,1,1)), "no solution", IF(ISERROR(INDEX('Sustainability Impact Analysis'!$C$40,1,1)), "error in parsing the solution", INDEX('Sustainability Impact Analysis'!$C$40,1,1))) -> 28.365855 | E10: =IFERROR(_xlfn.FORMULATEXT(INDEX('Sustainability Impact Analysis'!$C$40,1,1)),"no formula") -> =AVERAGEIF(I2:I19720,"Laptop",M2:M19720)
A11: Part 3, 4 | B11: 28.768725 | C11: 0.01 | D11: =IF(ISBLANK(INDEX('Sustainability Impact Analysis'!$C$41,1,1)), "no solution", IF(ISERROR(INDEX('Sustainability Impact Analysis'!$C$41,1,1)), "error in parsing the solution", INDEX('Sustainability Impact Analysis'!$C$41,1,1))) -> 28.768725 | E11: =IFERROR(_xlfn.FORMULATEXT(INDEX('Sustainability Impact Analysis'!$C$41,1,1)),"no formula") -> =AVERAGEIF(I2:I19720,"*desktop*",M2:M19720)
